Workbook

Sheet Scoreboard
A1: Delivery Scoreboard, per owner. Kurt only.
A2: Private file: individual scores are not shared between team members. The shared tracker stays the team view of the work itself.
A3: Ivan, Jul call: was it delivered on time, yes, no, or faster; was it delivered at the level you expected. Resyncs are the quality signal. Computed from the Delivery Log tab.
A5: Owner | B5: Committed (Due set) | C5: Delivered | D5: Faster | E5: On time | F5: Late | G5: On time or faster | H5: Overdue (open) | I5: Avg resyncs
A6: JV Manlangit | B6: =SUMPRODUCT(('Delivery Log'!$A$4:$A$400=$A6)*('Delivery Log'!$H$4:$H$400<>"")) -> 0 | C6: =SUMPRODUCT(('Delivery Log'!$A$4:$A$400=$A6)*('Delivery Log'!$I$4:$I$400<>"")) -> 2 | D6: =SUMPRODUCT(('Delivery Log'!$A$4:$A$400=$A6)*('Delivery Log'!$I$4:$I$400<>"")*('Delivery Log'!$H$4:$H$400<>"")*('Delivery Log'!$I$4:$I$400<'Delivery Log'!$H$4:$H$400)) -> 0 | E6: =SUMPRODUCT(('Delivery Log'!$A$4:$A$400=$A6)*('Delivery Log'!$I$4:$I$400<>"")*('Delivery Log'!$H$4:$H$400<>"")*('Delivery Log'!$I$4:$I$400='Delivery Log'!$H$4:$H$400)) -> 0 | F6: =SUMPRODUCT(('Delivery Log'!$A$4:$A$400=$A6)*('Delivery Log'!$I$4:$I$400<>"")*('Delivery Log'!$H$4:$H$400<>"")*('Delivery Log'!$I$4:$I$400>'Delivery Log'!$H$4:$H$400)) -> 0 | G6: =IF(D6+E6+F6=0,"-",(D6+E6)/(D6+E6+F6)) -> - | H6: =SUMPRODUCT(('Delivery Log'!$A$4:$A$400=$A6)*('Delivery Log'!$H$4:$H$400<>"")*('Delivery Log'!$I$4:$I$400="")*('Delivery Log'!$C$4:$C$400<>"Completed")*('Delivery Log'!$C$4:$C$400<>"Cancelled")*('Delivery Log'!$H$4:$H$400<TODAY())) -> 0 | I6: =IFERROR(ROUND(AVERAGEIFS('Delivery Log'!$K$4:$K$400,'Delivery Log'!$A$4:$A$400,$A6),1),"-") -> -
A7: Anton Betia | B7: =SUMPRODUCT(('Delivery Log'!$A$4:$A$400=$A7)*('Delivery Log'!$H$4:$H$400<>"")) -> 1 | C7: =SUMPRODUCT(('Delivery Log'!$A$4:$A$400=$A7)*('Delivery Log'!$I$4:$I$400<>"")) -> 0 | D7: =SUMPRODUCT(('Delivery Log'!$A$4:$A$400=$A7)*('Delivery Log'!$I$4:$I$400<>"")*('Delivery Log'!$H$4:$H$400<>"")*('Delivery Log'!$I$4:$I$400<'Delivery Log'!$H$4:$H$400)) -> 0 | E7: =SUMPRODUCT(('Delivery Log'!$A$4:$A$400=$A7)*('Delivery Log'!$I$4:$I$400<>"")*('Delivery Log'!$H$4:$H$400<>"")*('Delivery Log'!$I$4:$I$400='Delivery Log'!$H$4:$H$400)) -> 0 | F7: =SUMPRODUCT(('Delivery Log'!$A$4:$A$400=$A7)*('Delivery Log'!$I$4:$I$400<>"")*('Delivery Log'!$H$4:$H$400<>"")*('Delivery Log'!$I$4:$I$400>'Delivery Log'!$H$4:$H$400)) -> 0 | G7: =IF(D7+E7+F7=0,"-",(D7+E7)/(D7+E7+F7)) -> - | H7: =SUMPRODUCT(('Delivery Log'!$A$4:$A$400=$A7)*('Delivery Log'!$H$4:$H$400<>"")*('Delivery Log'!$I$4:$I$400="")*('Delivery Log'!$C$4:$C$400<>"Completed")*('Delivery Log'!$C$4:$C$400<>"Cancelled")*('Delivery Log'!$H$4:$H$400<TODAY())) -> 0 | I7: =IFERROR(ROUND(AVERAGEIFS('Delivery Log'!$K$4:$K$400,'Delivery Log'!$A$4:$A$400,$A7),1),"-") -> -
A8: Manzil Balani | B8: =SUMPRODUCT(('Delivery Log'!$A$4:$A$400=$A8)*('Delivery Log'!$H$4:$H$400<>"")) -> 0 | C8: =SUMPRODUCT(('Delivery Log'!$A$4:$A$400=$A8)*('Delivery Log'!$I$4:$I$400<>"")) -> 1 | D8: =SUMPRODUCT(('Delivery Log'!$A$4:$A$400=$A8)*('Delivery Log'!$I$4:$I$400<>"")*('Delivery Log'!$H$4:$H$400<>"")*('Delivery Log'!$I$4:$I$400<'Delivery Log'!$H$4:$H$400)) -> 0 | E8: =SUMPRODUCT(('Delivery Log'!$A$4:$A$400=$A8)*('Delivery Log'!$I$4:$I$400<>"")*('Delivery Log'!$H$4:$H$400<>"")*('Delivery Log'!$I$4:$I$400='Delivery Log'!$H$4:$H$400)) -> 0 | F8: =SUMPRODUCT(('Delivery Log'!$A$4:$A$400=$A8)*('Delivery Log'!$I$4:$I$400<>"")*('Delivery Log'!$H$4:$H$400<>"")*('Delivery Log'!$I$4:$I$400>'Delivery Log'!$H$4:$H$400)) -> 0 | G8: =IF(D8+E8+F8=0,"-",(D8+E8)/(D8+E8+F8)) -> - | H8: =SUMPRODUCT(('Delivery Log'!$A$4:$A$400=$A8)*('Delivery Log'!$H$4:$H$400<>"")*('Delivery Log'!$I$4:$I$400="")*('Delivery Log'!$C$4:$C$400<>"Completed")*('Delivery Log'!$C$4:$C$400<>"Cancelled")*('Delivery Log'!$H$4:$H$400<TODAY())) -> 0 | I8: =IFERROR(ROUND(AVERAGEIFS('Delivery Log'!$K$4:$K$400,'Delivery Log'!$A$4:$A$400,$A8),1),"-") -> -
A9: Elias Marcella | B9: =SUMPRODUCT(('Delivery Log'!$A$4:$A$400=$A9)*('Delivery Log'!$H$4:$H$400<>"")) -> 0 | C9: =SUMPRODUCT(('Delivery Log'!$A$4:$A$400=$A9)*('Delivery Log'!$I$4:$I$400<>"")) -> 0 | D9: =SUMPRODUCT(('Delivery Log'!$A$4:$A$400=$A9)*('Delivery Log'!$I$4:$I$400<>"")*('Delivery Log'!$H$4:$H$400<>"")*('Delivery Log'!$I$4:$I$400<'Delivery Log'!$H$4:$H$400)) -> 0 | E9: =SUMPRODUCT(('Delivery Log'!$A$4:$A$400=$A9)*('Delivery Log'!$I$4:$I$400<>"")*('Delivery Log'!$H$4:$H$400<>"")*('Delivery Log'!$I$4:$I$400='Delivery Log'!$H$4:$H$400)) -> 0 | F9: =SUMPRODUCT(('Delivery Log'!$A$4:$A$400=$A9)*('Delivery Log'!$I$4:$I$400<>"")*('Delivery Log'!$H$4:$H$400<>"")*('Delivery Log'!$I$4:$I$400>'Delivery Log'!$H$4:$H$400)) -> 0 | G9: =IF(D9+E9+F9=0,"-",(D9+E9)/(D9+E9+F9)) -> - | H9: =SUMPRODUCT(('Delivery Log'!$A$4:$A$400=$A9)*('Delivery Log'!$H$4:$H$400<>"")*('Delivery Log'!$I$4:$I$400="")*('Delivery Log'!$C$4:$C$400<>"Completed")*('Delivery Log'!$C$4:$C$400<>"Cancelled")*('Delivery Log'!$H$4:$H$400<TODAY())) -> 0 | I9: =IFERROR(ROUND(AVERAGEIFS('Delivery Log'!$K$4:$K$400,'Delivery Log'!$A$4:$A$400,$A9),1),"-") -> -
A10: Jastin Lagumbay | B10: =SUMPRODUCT(('Delivery Log'!$A$4:$A$400=$A10)*('Delivery Log'!$H$4:$H$400<>"")) -> 0 | C10: =SUMPRODUCT(('Delivery Log'!$A$4:$A$400=$A10)*('Delivery Log'!$I$4:$I$400<>"")) -> 0 | D10: =SUMPRODUCT(('Delivery Log'!$A$4:$A$400=$A10)*('Delivery Log'!$I$4:$I$400<>"")*('Delivery Log'!$H$4:$H$400<>"")*('Delivery Log'!$I$4:$I$400<'Delivery Log'!$H$4:$H$400)) -> 0 | E10: =SUMPRODUCT(('Delivery Log'!$A$4:$A$400=$A10)*('Delivery Log'!$I$4:$I$400<>"")*('Delivery Log'!$H$4:$H$400<>"")*('Delivery Log'!$I$4:$I$400='Delivery Log'!$H$4:$H$400)) -> 0 | F10: =SUMPRODUCT(('Delivery Log'!$A$4:$A$400=$A10)*('Delivery Log'!$I$4:$I$400<>"")*('Delivery Log'!$H$4:$H$400<>"")*('Delivery Log'!$I$4:$I$400>'Delivery Log'!$H$4:$H$400)) -> 0 | G10: =IF(D10+E10+F10=0,"-",(D10+E10)/(D10+E10+F10)) -> - | H10: =SUMPRODUCT(('Delivery Log'!$A$4:$A$400=$A10)*('Delivery Log'!$H$4:$H$400<>"")*('Delivery Log'!$I$4:$I$400="")*('Delivery Log'!$C$4:$C$400<>"Completed")*('Delivery Log'!$C$4:$C$400<>"Cancelled")*('Delivery Log'!$H$4:$H$400<TODAY())) -> 0 | I10: =IFERROR(ROUND(AVERAGEIFS('Delivery Log'!$K$4:$K$400,'Delivery Log'!$A$4:$A$400,$A10),1),"-") -> -
A11: Team | B11: =SUM(B6:B10) -> 1 | C11: =SUM(C6:C10) -> 3 | D11: =SUM(D6:D10) -> 0 | E11: =SUM(E6:E10) -> 0 | F11: =SUM(F6:F10) -> 0 | G11: =IF(D11+E11+F11=0,"-",(D11+E11)/(D11+E11+F11)) -> - | H11: =SUM(H6:H10) -> 0
A13: How to read it: Committed = rows with an agreed Due date. Speed needs Due dates, so set them at standup; a delivery without a Due date cannot be scored.
A14: Refresh weekly: copy rows A4 down to M from the tracker's Master Rollup and paste into the Delivery Log tab (same columns). In Google Sheets, the Delivery Log tab can be replaced with IMPORTRANGE for auto-sync.
A15: Feeds the quarterly Revolut-style scorecard: Speed from on time or faster, Quality from resyncs and level delivered, Complexity judged per project. Deliverables = (Speed + Quality) x Complexity.

Sheet Delivery Log
A1: Mirror of the tracker Master Rollup (columns A to M). Refresh by paste, or IMPORTRANGE in Google Sheets. The Scoreboard reads Owner (A), Status (C), Due (H), Delivered (I), Resyncs (K).
A3: Owner | B3: Project | C3: Status | D3: Priority | E3: KPI Key Driver | F3: Impact (bottom-up) | G3: Added | H3: Due | I3: Delivered | J3: Speed | K3: Resyncs | L3: Summary | M3: ClickUp / BRD Link
A4: JV Manlangit | B4: SAP Video Capture | C4: In Progress | D4: Urgent | E4: SAP - D2 Disbursement per active agent | J4: =IF(I4="","",IF(H4="","-",IF(I4<H4,"Faster",IF(I4=H4,"On time","Late")))) | L4: Video statement capture for high-risk clients with AI transcript + facial verification. Phase 1 live. AI status update pending. | M4: https://app.clickup.com/t/86ewdm810
A5: Anton Betia | B5: Item-Based Pricing | C5: Blocked | D5: Urgent | E5: Pricing - Merchants (Chi) | J5: =IF(I5="","",IF(H5="","-",IF(I5<H5,"Faster",IF(I5=H5,"On time","Late")))) | L5: Apply promo rules to selected products, not whole catalog. Part of products engine. awaiting merchant requirements. | M5: https://app.clickup.com/t/86ewdm7xz
A6: Elias Marcella | B6: Credit Line (Launch) | C6: In Progress | D6: Urgent | E6: Credit Line - D1 Utilization & drawdown | F6: CL utilization and drawdown, target set ~30 days post-launch | J6: =IF(I6="","",IF(H6="","-",IF(I6<H6,"Faster",IF(I6=H6,"On time","Late")))) | L6: Launched 15 Jul (F&F/ETB). Phase-1 open: repayment/statement emails, eligibility, biz events, web FAQ, pending-txn spec. Refund/chargeback & IPP later phases. | M6: https://app.clickup.com/t/9008174123/86eyaav7k
A7: JV Manlangit | B7: Motorcycle Loans (KServico) | C7: In Progress | D7: High | E7: Motorcycles - D1 Moto monthly disbursement | F7: Moto monthly run rate, gated by Nhat | J7: =IF(I7="","",IF(H7="","-",IF(I7<H7,"Faster",IF(I7=H7,"On time","Late")))) | L7: Addendum & SA guide done, delivered via SAP. refresher pending. return-config changes being finalized. | M7: https://app.clickup.com/t/9008174123/86ey83p6c
A8: Anton Betia | B8: Special Deals Offer to Low-Risk Customers | C8: In Progress | D8: High | E8: Deals - D1 Monthly disbursement | F8: Conversion lift on low-risk base, size with Nhat before comms | H8: 46223 | J8: =IF(I8="","",IF(H8="","-",IF(I8<H8,"Faster",IF(I8=H8,"On time","Late")))) | L8: Additional-limit offer to low-risk clients to lift conversion. DE deployed. comms Jul 20. | M8: https://app.clickup.com/t/9008174123/86exz94uf
A9: Anton Betia | B9: Deals API Documentation | C9: In Progress | D9: High | E9: Deals - D1 Monthly disbursement | J9: =IF(I9="","",IF(H9="","-",IF(I9<H9,"Faster",IF(I9=H9,"On time","Late")))) | L9: Gather partner API docs (Giftaway, 3Cat) to scope integration timeline. | M9: https://app.clickup.com/t/9008174123/86ey90pqa
A10: Anton Betia | B10: Vouchers on Deals | C10: In Progress | D10: High | E10: Deals - D1 Monthly disbursement | J10: =IF(I10="","",IF(H10="","-",IF(I10<H10,"Faster",IF(I10=H10,"On time","Late")))) | L10: Enable voucher purchases on Deals. preparing rails. | M10: https://app.clickup.com/t/9008174123/86eyadmt7
A11: Anton Betia | B11: Launch Deals on Web | C11: In Progress | D11: High | E11: Deals - D3 Delivery on roadmap | J11: =IF(I11="","",IF(H11="","-",IF(I11<H11,"Faster",IF(I11=H11,"On time","Late")))) | L11: Web version of Deals. Phase 1 UI testing paused as of Jul 15.
A12: Manzil Balani | B12: Deals Merchant BD Pipeline | C12: In Progress | D12: High | E12: Deals BD - D2 New merchants live & disbursing | F12: New merchants live and disbursing, ticket uplift | J12: =IF(I12="","",IF(H12="","-",IF(I12<H12,"Faster",IF(I12=H12,"On time","Late")))) | L12: Brand pipeline. WARM: Kimstore, 3Cat, Hati, Laptop Factory, Samsung, PrimerGrp, PowerMac, AirAsia, Qoala. Rejected: MetroMart, Engkanto, DataBlitz, Vivo, Mandaue Foam. | M12: https://docs.google.com/spreadsheets/d/1Qx9NB9uO7TvVACgTXQszWOwBFCa_OTElUIsEwWYCVOM/
A13: Elias Marcella | B13: Access Card | C13: In Progress | D13: High | E13: Card - D2 Card unit economics | F13: Per-card break-even on interchange at target CAC | J13: =IF(I13="","",IF(H13="","-",IF(I13<H13,"Faster",IF(I13=H13,"On time","Late")))) | L13: BillEase Mastercard (numberless) w/ AUB & MatchMove. MOA negotiation (audit cap, CS cert, VAPT). design + bureau RFPs out. activation BRD done. Target prod Q4 2026. | M13: https://docs.google.com/spreadsheets/d/1Vf8kaBSoQp1PeSw156nCNtYON_3ZJM5ZbR9xZPe8SjU/
A14: Elias Marcella | B14: Risk-Based Pricing | C14: Blocked | D14: High | E14: Pricing - Merchants/Risk | J14: =IF(I14="","",IF(H14="","-",IF(I14<H14,"Faster",IF(I14=H14,"On time","Late")))) | L14: Dynamic interest rates by client credit behaviour. Part of products engine. awaiting requirements. | M14: https://app.clickup.com/t/86ewn2hpd
A15: Jastin Lagumbay | B15: SM Appliances - Acknowledgement Receipt | C15: In Progress | D15: High | E15: Merchant Onboarding - D2 Onboarding cycle time | J15: =IF(I15="","",IF(H15="","-",IF(I15<H15,"Faster",IF(I15=H15,"On time","Late")))) | L15: Read-only approved-transaction receipt for merchants (75%). Dev done. awaiting SM signatory. | M15: https://app.clickup.com/t/86ewpkfpv
A16: Jastin Lagumbay | B16: Supervisors/RMs Stamp in Create Trx Report | C16: In Progress | D16: High | E16: Merchant Onboarding - D2 Onboarding cycle time | J16: =IF(I16="","",IF(H16="","-",IF(I16<H16,"Faster",IF(I16=H16,"On time","Late")))) | L16: Adds supervisor/RM stamp to Create Trx Report (83%). Live for txns after Jun 16. validating incentives. | M16: https://app.clickup.com/t/86ex68b0u
A17: Jastin Lagumbay | B17: QRPh Chargeback Escalation (Netbank/AUB) | C17: In Progress | D17: High | E17: QRPh - D1 Monthly disbursement run rate | F17: Protects the QRPh run rate | J17: =IF(I17="","",IF(H17="","-",IF(I17<H17,"Faster",IF(I17=H17,"On time","Late")))) | L17: Daily QRPh chargeback escalation & checking for AUB and Netbank. | M17: https://app.clickup.com/t/9008174123/86ey9ztg7
A18: Jastin Lagumbay | B18: Merchant Onboarding Ops Queue (BAU) | C18: In Progress | D18: High | E18: Merchant Onboarding - D2 Onboarding cycle time | J18: =IF(I18="","",IF(H18="","-",IF(I18<H18,"Faster",IF(I18=H18,"On time","Late")))) | L18: Daily BAU queue: shop/user/bank adds, onboarding, branch/name changes. ~20+ tickets/week, mostly same/next-day. | M18: https://docs.google.com/spreadsheets/d/1FXbhtIl3aNyH9zr5Zf_xpV_OaLrUeQVwTLEMQKsn_dg/
A19: Jastin Lagumbay | B19: Product Pricing / SAP Calculator PVT | C19: In Progress | D19: High | E19: IT/PVT - Billy (D1 release quality gate) | J19: =IF(I19="","",IF(H19="","-",IF(I19<H19,"Faster",IF(I19=H19,"On time","Late")))) | L19: Pricing/tenor/IR validation across merchant scenarios (Android/iOS). Recent Fails at FC Home Lubao 3 & Shaw need config fix. | M19: https://docs.google.com/spreadsheets/d/178O3aMK18zV_j96Xbp6UD3-QWxWX9QIFjTOju0fw-sM/
A20: JV Manlangit | B20: Promoter Referral Program v2: Online Linking | C20: In Progress | D20: Normal | E20: SAP - D2 Disbursement per active agent | J20: =IF(I20="","",IF(H20="","-",IF(I20<H20,"Faster",IF(I20=H20,"On time","Late")))) | L20: Extends referral program to online transactions. BRD in progress. validation shifting to Merchants/Billease. | M20: https://app.clickup.com/9008174123/v/dc/8cevn1b-45778/8cevn1b-224358
A21: JV Manlangit | B21: Feedback Form for Non-Converted Sign-ups | C21: In Progress | D21: Normal | E21: SAP - D2 Disbursement per active agent | J21: =IF(I21="","",IF(H21="","-",IF(I21<H21,"Faster",IF(I21=H21,"On time","Late")))) | L21: Captures friction on agents' unconverted leads (25%). Adding conditional-question feature. | M21: https://app.clickup.com/t/86ewphrkt
A22: JV Manlangit | B22: SAP Calculator | C22: In Progress | D22: Normal | E22: SAP - D2 Disbursement per active agent | J22: =IF(I22="","",IF(H22="","-",IF(I22<H22,"Faster",IF(I22=H22,"On time","Late")))) | L22: Real-time SAP loan calculator from product config (40%). Mockup + ticket done. dev pending. | M22: https://app.clickup.com/t/86ex68cg9
A23: JV Manlangit | B23: SAP Looker Dashboard | C23: In Progress | D23: Normal | E23: BI - Jenny Ho (D1 dashboard) | J23: =IF(I23="","",IF(H23="","-",IF(I23<H23,"Faster",IF(I23=H23,"On time","Late")))) | L23: Looker reporting for Trx Requests, Non-Converted Sign-ups & future SAP projects (50%). Dev pending. | M23: https://app.clickup.com/t/86ewqfqqa
A24: Anton Betia | B24: Deals UX Study | C24: In Progress | D24: Normal | E24: Deals - D2 Acceptance/conversion | J24: =IF(I24="","",IF(H24="","-",IF(I24<H24,"Faster",IF(I24=H24,"On time","Late")))) | L24: UX study: brand-first vs agnostic Deals store. Regroup call scheduled.
A25: Anton Betia | B25: Multi-item per Merchant | C25: In Progress | D25: Normal | E25: Deals - D1 Monthly disbursement | J25: =IF(I25="","",IF(H25="","-",IF(I25<H25,"Faster",IF(I25=H25,"On time","Late")))) | L25: Same product across merchants with price-comparison screen. BRD drafted. design pending. | M25: https://app.clickup.com/t/9008174123/86ey9gdq1
A26: Anton Betia | B26: Location-Based Delivery | C26: In Progress | D26: Normal | E26: Deals - D1 Monthly disbursement | J26: =IF(I26="","",IF(H26="","-",IF(I26<H26,"Faster",IF(I26=H26,"On time","Late")))) | L26: Support coordinates + flag out-of-range deliveries. BRD + mockup for Kurt's input. | M26: https://app.clickup.com/t/9008174123/86eyavqf4
A27: Anton Betia | B27: Pick-Up Model | C27: In Progress | D27: Normal | E27: Deals - D1 Monthly disbursement | J27: =IF(I27="","",IF(H27="","-",IF(I27<H27,"Faster",IF(I27=H27,"On time","Late")))) | L27: Pickup-location fulfillment option instead of delivery. BRD + mockup for Kurt's input. | M27: https://app.clickup.com/t/9008174123/86eyavtqg
A28: Anton Betia | B28: Support for Pre-Owned on Deals | C28: Not Started | D28: Normal | E28: Deals - D1 Monthly disbursement | J28: =IF(I28="","",IF(H28="","-",IF(I28<H28,"Faster",IF(I28=H28,"On time","Late")))) | L28: Prepare rails for pre-owned listings (3Cat). Rails list being scoped. | M28: https://app.clickup.com/t/9008174123/86eyafcd5
A29: Anton Betia | B29: Credit Line for Deals | C29: Not Started | D29: Normal | E29: Deals - D1 Monthly disbursement | J29: =IF(I29="","",IF(H29="","-",IF(I29<H29,"Faster",IF(I29=H29,"On time","Late")))) | L29: Integrate Deals with Credit Line. Target August. | M29: https://app.clickup.com/t/9008174123/86ey7mar5
A30: Anton Betia | B30: Deals 360 Dashboard | C30: Not Started | D30: Normal | E30: BI - Jenny Ho (D1 dashboard) | J30: =IF(I30="","",IF(H30="","-",IF(I30<H30,"Faster",IF(I30=H30,"On time","Late")))) | L30: Expanded Deals 360 dashboard. requested columns from Jenny. | M30: https://app.clickup.com/t/9008174123/86ey90puc
A31: Manzil Balani | B31: Adding Missing Deals Items | C31: In Progress | D31: Normal | E31: Deals BD - D2 New merchants live | J31: =IF(I31="","",IF(H31="","-",IF(I31<H31,"Faster",IF(I31=H31,"On time","Late")))) | L31: Add products missing from Deals inventory. List provided. items pending.
A32: Jastin Lagumbay | B32: Integrate Merchant Guide to Billease Docs | C32: Not Started | D32: Normal | E32: Merchant Onboarding - D2 Onboarding cycle time | F32: Fewer onboarding tickets via self-serve guide | J32: =IF(I32="","",IF(H32="","-",IF(I32<H32,"Faster",IF(I32=H32,"On time","Late")))) | L32: Single self-service Merchant Guide: handbook + 7 walkthroughs, vector screens, PII redaction. Target 30% fewer tickets. | M32: https://app.clickup.com/t/9008174123/86exz70h6
A33: Jastin Lagumbay | B33: Automate Onboarding Email | C33: Not Started | D33: Normal | E33: Merchant Onboarding - D2 Onboarding cycle time | J33: =IF(I33="","",IF(H33="","-",IF(I33<H33,"Faster",IF(I33=H33,"On time","Late")))) | L33: Auto welcome email on first transition to Active (once only), with logging + retry. | M33: https://app.clickup.com/t/9008174123/86ev2ktw2
A34: Jastin Lagumbay | B34: Update 'How to Become a Merchant' Page | C34: Not Started | D34: Normal | E34: Merchant Onboarding - D2 Onboarding cycle time | J34: =IF(I34="","",IF(H34="","-",IF(I34<H34,"Faster",IF(I34=H34,"On time","Late")))) | L34: Add rejection screen linking to QRPh FAQs. keep success screen largely the same. | M34: https://app.clickup.com/t/9008174123/86ey3qbz2
A35: JV Manlangit | B35: SAP Announcement & Quiz Module v2 | C35: In Progress | D35: Low | E35: SAP - D2 Disbursement per active agent | J35: =IF(I35="","",IF(H35="","-",IF(I35<H35,"Faster",IF(I35=H35,"On time","Late")))) | L35: v1 enhancements: editable-after-activation, duplicate forms, data filter by TL & SFT.
A36: JV Manlangit | B36: SAP Announcement & Quiz Module v1 | C36: Completed | D36: Urgent | E36: SAP - D2 Disbursement per active agent | I36: 46206 | J36: =IF(I36="","",IF(H36="","-",IF(I36<H36,"Faster",IF(I36=H36,"On time","Late")))) -> - | L36: Mandatory in-SAP info delivery + retention quiz per agent. Rolled to prod Jul 3. | M36: https://app.clickup.com/t/9008174123/86ey0ujv3
A37: JV Manlangit | B37: Early Upsell | C37: Completed | D37: Urgent | E37: SAP - D2 Disbursement per active agent | J37: =IF(I37="","",IF(H37="","-",IF(I37<H37,"Faster",IF(I37=H37,"On time","Late")))) | L37: Post-disbursement upsell leaflet + announcement/quiz. Live. ~94% completion as of Jul 10.
A38: JV Manlangit | B38: Credit Line - Agent Announcement (SAP) | C38: Completed | D38: Urgent | E38: SAP - D2 Disbursement per active agent | I38: 46219 | J38: =IF(I38="","",IF(H38="","-",IF(I38<H38,"Faster",IF(I38=H38,"On time","Late")))) -> - | L38: Credit Line announcement + quiz delivered to agents via SAP Jul 16.
A39: JV Manlangit | B39: Promoter Referral Program v1: Offline Linking | C39: Completed | D39: High | E39: SAP - D2 Disbursement per active agent | J39: =IF(I39="","",IF(H39="","-",IF(I39<H39,"Faster",IF(I39=H39,"On time","Late")))) | L39: Auto-rewards promoters for merchant-loan referrals (offline). Live. Giftaway credits monitored weekly. | M39: https://app.clickup.com/9008174123/v/dc/8cevn1b-45778/8cevn1b-219678
A40: Manzil Balani | B40: Maxicare PRIMA Launch on Deals | C40: Completed | D40: High | E40: Deals BD - D2 New merchants live | I40: 46213 | J40: =IF(I40="","",IF(H40="","-",IF(I40<H40,"Faster",IF(I40=H40,"On time","Late")))) -> - | L40: Maxicare PRIMA live on Deals Jul 10. first marketing blast Jul 21. iOS pending shorter descriptions.
A41: Anton Betia | B41: Adding Pay Later on Deals | C41: Cancelled | D41: Low | E41: Deals - D1 Monthly disbursement | J41: =IF(I41="","",IF(H41="","-",IF(I41<H41,"Faster",IF(I41=H41,"On time","Late")))) | L41: Pay Later / convert-to-installment on Deals. Cancelled - redundant with Credit Line. | M41: https://app.clickup.com/t/9008174123/86ew51ha3
...

Sheet Initiative Log
A1: Initiative Log: the growth dimension (not bonus)
A2: Ivan, Jul call: you cannot grow if you do not do initiatives. Track who connects the numbers to actions. Assess each idea easy vs difficult and high vs low impact; it gets its own priority; then run it.
A4: Date | B4: Person | C4: Initiative (problem, proposed action) | D4: Effort | E4: Impact | F4: Priority (auto) | G4: Status | H4: Notes
A5: 46223 | B5: Anton Betia | C5: Deals listing sorts P9,999 item first while the popular P1,000 item is last; add cheapest-first sorting | D5: Easy | E5: High | F5: =IF(OR(D5="",E5=""),"",IF(AND(D5="Easy",E5="High"),"P1 do now",IF(E5="High","P2 plan",IF(D5="Easy","P3 quick win","P4 later")))) -> P1 do now | G5: In tracker | H5: Raised by Ivan on the Jul call; Kurt committed the fix
F6: =IF(OR(D6="",E6=""),"",IF(AND(D6="Easy",E6="High"),"P1 do now",IF(E6="High","P2 plan",IF(D6="Easy","P3 quick win","P4 later"))))
F7: =IF(OR(D7="",E7=""),"",IF(AND(D7="Easy",E7="High"),"P1 do now",IF(E7="High","P2 plan",IF(D7="Easy","P3 quick win","P4 later"))))
F8: =IF(OR(D8="",E8=""),"",IF(AND(D8="Easy",E8="High"),"P1 do now",IF(E8="High","P2 plan",IF(D8="Easy","P3 quick win","P4 later"))))
F9: =IF(OR(D9="",E9=""),"",IF(AND(D9="Easy",E9="High"),"P1 do now",IF(E9="High","P2 plan",IF(D9="Easy","P3 quick win","P4 later"))))
F10: =IF(OR(D10="",E10=""),"",IF(AND(D10="Easy",E10="High"),"P1 do now",IF(E10="High","P2 plan",IF(D10="Easy","P3 quick win","P4 later"))))
F11: =IF(OR(D11="",E11=""),"",IF(AND(D11="Easy",E11="High"),"P1 do now",IF(E11="High","P2 plan",IF(D11="Easy","P3 quick win","P4 later"))))
F12: =IF(OR(D12="",E12=""),"",IF(AND(D12="Easy",E12="High"),"P1 do now",IF(E12="High","P2 plan",IF(D12="Easy","P3 quick win","P4 later"))))
F13: =IF(OR(D13="",E13=""),"",IF(AND(D13="Easy",E13="High"),"P1 do now",IF(E13="High","P2 plan",IF(D13="Easy","P3 quick win","P4 later"))))
F14: =IF(OR(D14="",E14=""),"",IF(AND(D14="Easy",E14="High"),"P1 do now",IF(E14="High","P2 plan",IF(D14="Easy","P3 quick win","P4 later"))))
F15: =IF(OR(D15="",E15=""),"",IF(AND(D15="Easy",E15="High"),"P1 do now",IF(E15="High","P2 plan",IF(D15="Easy","P3 quick win","P4 later"))))
F16: =IF(OR(D16="",E16=""),"",IF(AND(D16="Easy",E16="High"),"P1 do now",IF(E16="High","P2 plan",IF(D16="Easy","P3 quick win","P4 later"))))
F17: =IF(OR(D17="",E17=""),"",IF(AND(D17="Easy",E17="High"),"P1 do now",IF(E17="High","P2 plan",IF(D17="Easy","P3 quick win","P4 later"))))
... F39: =IF(OR(D39="",E39=""),"",IF(AND(D39="Easy",E39="High"),"P1 do now",IF(E39="High","P2 plan",IF(D39="Easy","P3 quick win","P4 later"))))

Sheet Calibration
A1: Calibration: one score per person (5 to 1)
A2: Run NOW for the past 3 months; do not wait for the December review (Ivan, Jul call). Compare the result to your gut feel; when it corresponds, adopt it. How you arrive at the score, no one cares; the score is what calibrates.
A3: The bar is the person, not the peer: "I am not comparing you with him. I am comparing your bar with your performance." Juniors get a mistake discount; non-juniors must arrive fully thought through.
A5: Person | B5: Seniority (the bar) | C5: On time or faster | D5: Avg resyncs | E5: Initiatives | F5: Scorecard overall grade | G5: Score (5-1) | H5: Notes / evidence
A6: JV Manlangit | C6: =IFERROR(INDEX(Scoreboard!$G$6:$G$10,MATCH($A6,Scoreboard!$A$6:$A$10,0)),"-") -> - | D6: =IFERROR(INDEX(Scoreboard!$I$6:$I$10,MATCH($A6,Scoreboard!$A$6:$A$10,0)),"-") -> - | E6: =COUNTIFS('Initiative Log'!$B$5:$B$39,$A6) -> 0
A7: Anton Betia | C7: =IFERROR(INDEX(Scoreboard!$G$6:$G$10,MATCH($A7,Scoreboard!$A$6:$A$10,0)),"-") -> - | D7: =IFERROR(INDEX(Scoreboard!$I$6:$I$10,MATCH($A7,Scoreboard!$A$6:$A$10,0)),"-") -> - | E7: =COUNTIFS('Initiative Log'!$B$5:$B$39,$A7) -> 1
A8: Manzil Balani | C8: =IFERROR(INDEX(Scoreboard!$G$6:$G$10,MATCH($A8,Scoreboard!$A$6:$A$10,0)),"-") -> - | D8: =IFERROR(INDEX(Scoreboard!$I$6:$I$10,MATCH($A8,Scoreboard!$A$6:$A$10,0)),"-") -> - | E8: =COUNTIFS('Initiative Log'!$B$5:$B$39,$A8) -> 0
A9: Elias Marcella | B9: Senior | C9: =IFERROR(INDEX(Scoreboard!$G$6:$G$10,MATCH($A9,Scoreboard!$A$6:$A$10,0)),"-") -> - | D9: =IFERROR(INDEX(Scoreboard!$I$6:$I$10,MATCH($A9,Scoreboard!$A$6:$A$10,0)),"-") -> - | E9: =COUNTIFS('Initiative Log'!$B$5:$B$39,$A9) -> 0
A10: Jastin Lagumbay | C10: =IFERROR(INDEX(Scoreboard!$G$6:$G$10,MATCH($A10,Scoreboard!$A$6:$A$10,0)),"-") -> - | D10: =IFERROR(INDEX(Scoreboard!$I$6:$I$10,MATCH($A10,Scoreboard!$A$6:$A$10,0)),"-") -> - | E10: =COUNTIFS('Initiative Log'!$B$5:$B$39,$A10) -> 0
A12: Seniority for Elias per Ivan: superstar bar, well paid, the only discount is domain knowledge. Set the rest of the bars yourself and confirm with Ivan.
A13: Scorecard overall grade comes from each person's QuantumLight Product Owner scorecard (one copy per person per quarter). Yellow = fill by hand.
