Workbook

Sheet Assessment Scorecard
B1: Performance Review Template: Product Owner | K1: Download a copy to play with the file!
M3: Space for your KPIs
B4: Employee Full Name: | F4: Sample PM (illustrative, not a real person) | M4: KPI - Q3 26 | Q4: Achieved? | R4: Link
B5: Seniority: | F5: Mid | M5: D1 line outcome: monthly disbursement vs target (P__, TBD with Ivan) | Q5: TBD end Q3 | R5: Tracker: KPI Targets H2
B6: Culture Grade | F6: =IFERROR(IF(MIN(Parameters!$J$25:$L$25)<0,"Underperformer",IF(MIN(Parameters!$J$25:$L$25)>=1,"A-player","Above the Bar")),"TBC") -> Above the Bar | M6: D2 key driver: acceptance and conversion vs target (TBD) | Q6: TBD end Q3 | R6: Tracker: KPI Targets H2
B7: Deliverables Grade | F7: =IFERROR(IF($G$15<0,"Underperformer",IF($G$15>=2,"A-player","Above the Bar")),"TBC") -> Above the Bar | M7: D3 delivery: agreed roadmap steps shipped on pace (on-time rate) | Q7: On track | R7: Delivery Scoreboard
B8: Skills Grade | F8: =IFERROR(IF(MIN(Parameters!$N$25:$P$25)<0,"Underperformer",IF(MIN(Parameters!$N$25:$P$25)>=1,"A-player","Above the Bar")),"TBC") -> A-player
B9: Overall Grade | F9: =IFERROR(IF(COUNTIFS($F$6:$F$8,"Underperformer")>0,"Underperformer",IF(COUNTIFS($F$6:$F$8,"A-player")>1,"A-player","Above The Bar")),"TBC") -> Above The Bar
M10: Space for Feedback
F11: Your Score | G11: Diff | H11: Talent Bar | M11: Strengths
B12: Culture | D12: Dream Team | F12: =W38 -> Intermediate | G12: {=INDEX(Parameters!$D$5:$D$9,MATCH(F12,Parameters!$B$5:$B$9,0))-INDEX(Parameters!$D$5:$D$9,MATCH(H12,Parameters!$B$5:$B$9,0))} -> 1 | H12: {=IFERROR(INDEX(Parameters!$C$17:$I$20,MATCH($F$5,Parameters!$B$17:$B$20,0),MATCH(D12,Parameters!$C$16:$I$16,0)),"TBC")} -> Basic | M12: Owns problems end to end, strong bias to action
D13: Push the Limits | F13: =W59 -> Basic | G13: {=INDEX(Parameters!$D$5:$D$9,MATCH(F13,Parameters!$B$5:$B$9,0))-INDEX(Parameters!$D$5:$D$9,MATCH(H13,Parameters!$B$5:$B$9,0))} -> 0 | H13: {=IFERROR(INDEX(Parameters!$C$17:$I$20,MATCH($F$5,Parameters!$B$17:$B$20,0),MATCH(D13,Parameters!$C$16:$I$16,0)),"TBC")} -> Basic | M13: Data-driven prioritization, solid grasp of the metric tree
D14: Get It Done | F14: =W70 -> Intermediate | G14: {=INDEX(Parameters!$D$5:$D$9,MATCH(F14,Parameters!$B$5:$B$9,0))-INDEX(Parameters!$D$5:$D$9,MATCH(H14,Parameters!$B$5:$B$9,0))} -> 1 | H14: {=IFERROR(INDEX(Parameters!$C$17:$I$20,MATCH($F$5,Parameters!$B$17:$B$20,0),MATCH(D14,Parameters!$C$16:$I$16,0)),"TBC")} -> Basic | M14: Reliable delivery track record in the exec tracker
B15: Deliverables Score | F15: =W89 -> Advanced | G15: {=INDEX(Parameters!$D$5:$D$9,MATCH(F15,Parameters!$B$5:$B$9,0))-INDEX(Parameters!$D$5:$D$9,MATCH(H15,Parameters!$B$5:$B$9,0))} -> 1 | H15: {=IFERROR(INDEX(Parameters!$C$17:$I$20,MATCH($F$5,Parameters!$B$17:$B$20,0),MATCH("Deliverables",Parameters!$C$16:$I$16,0)),"TBC")} -> Intermediate | M15: Improvement Areas
B16: Skills | D16: Problem Solving | F16: =W99 -> Advanced | G16: {=INDEX(Parameters!$D$5:$D$9,MATCH(F16,Parameters!$B$5:$B$9,0))-INDEX(Parameters!$D$5:$D$9,MATCH(H16,Parameters!$B$5:$B$9,0))} -> 1 | H16: {=IFERROR(INDEX(Parameters!$C$17:$I$20,MATCH($F$5,Parameters!$B$17:$B$20,0),MATCH(D16,Parameters!$C$16:$I$16,0)),"TBC")} -> Intermediate | M16: Push the limits: propose new levers, not only execute the agreed ones
D17: Lifecycle Management | F17: =W112 -> Intermediate | G17: {=INDEX(Parameters!$D$5:$D$9,MATCH(F17,Parameters!$B$5:$B$9,0))-INDEX(Parameters!$D$5:$D$9,MATCH(H17,Parameters!$B$5:$B$9,0))} -> 1 | H17: {=IFERROR(INDEX(Parameters!$C$17:$I$20,MATCH($F$5,Parameters!$B$17:$B$20,0),MATCH(D17,Parameters!$C$16:$I$16,0)),"TBC")} -> Basic | M17: Sharpen margin and risk diagnosis (Tier 2 questions)
D18: Product Sense | F18: =W134 -> Intermediate | G18: {=INDEX(Parameters!$D$5:$D$9,MATCH(F18,Parameters!$B$5:$B$9,0))-INDEX(Parameters!$D$5:$D$9,MATCH(H18,Parameters!$B$5:$B$9,0))} -> 1 | H18: {=IFERROR(INDEX(Parameters!$C$17:$I$20,MATCH($F$5,Parameters!$B$17:$B$20,0),MATCH(D18,Parameters!$C$16:$I$16,0)),"TBC")} -> Basic | M18: Raise first-pass quality to cut iterations to done
F20: Score | H20: Description | M20: Yes/No | N20: Value | O20: Toggle | P20: Adj Val | Q20: Examples
B22: Culture (based on QuantumLight's own values) | D22: Dream Team | F22: POOR | H22: Close minded and defensive | M22: No | N22: =1/COUNTA(H22:H25) -> 0.25 | O22: =IF(M22="No",1,0) -> 1 | P22: =O22*N22 -> 0.25
F23: POOR | H23: Obviously political in behaviour | M23: No | N23: =N22 -> 0.25 | O23: =IF(M23="No",1,0) -> 1 | P23: =O23*N23 -> 0.25
F24: POOR | H24: Emotional to direct feedback | M24: No | N24: =N23 -> 0.25 | O24: =IF(M24="No",1,0) -> 1 | P24: =O24*N24 -> 0.25
F25: POOR | H25: Low talent bar | M25: No | N25: =N24 -> 0.25 | O25: =IF(M25="No",1,0) -> 1 | P25: =O25*N25 -> 0.25
F26: BASIC | H26: An open-minded, calm approach to harsh feedback | M26: Yes | N26: =1/COUNTA($H$26:$H$28) -> 0.33333333 | O26: =IF(M26="Yes",1,0) -> 1 | P26: =IF(SUMIFS($P$22:$P25,$F$22:$F25,"POOR")=1,O26*N26,0) -> 0.33333333
F27: BASIC | H27: Respectfully delivers candid feedback in a non-personal way | M27: Yes | N27: =1/COUNTA($H$26:$H$28) -> 0.33333333 | O27: =IF(M27="Yes",1,0) -> 1 | P27: =IF(SUMIFS($P$22:$P26,$F$22:$F26,"POOR")=1,O27*N27,0) -> 0.33333333
F28: BASIC | H28: Does not play politics, puts company interests ahead of their own | M28: Yes | N28: =1/COUNTA($H$26:$H$28) -> 0.33333333 | O28: =IF(M28="Yes",1,0) -> 1 | P28: =IF(SUMIFS($P$22:$P27,$F$22:$F27,"POOR")=1,O28*N28,0) -> 0.33333333
F29: INTERMEDIATE | H29: Driver, not a passenger - initiates, leads, motivates others | M29: Yes | N29: =1/COUNTA($H$29:$H$31) -> 0.33333333 | O29: =IF(M29="Yes",1,0) -> 1 | P29: =IF(SUMIFS($P$22:$P28,$F$22:$F28,"BASIC")=1,O29*N29,0) -> 0.33333333
F30: INTERMEDIATE | H30: Establishes an emotional connection early to maximise performance | M30: Yes | N30: =N29 -> 0.33333333 | O30: =IF(M30="Yes",1,0) -> 1 | P30: =IF(SUMIFS($P$22:$P29,$F$22:$F29,"BASIC")=1,O30*N30,0) -> 0.33333333 | Q30: e.g. led partner sync during launch week without being asked
F31: INTERMEDIATE | H31: Tough coach: hires, keeps and develops only the best talent | M31: Yes | N31: =N30 -> 0.33333333 | O31: =IF(M31="Yes",1,0) -> 1 | P31: =IF(SUMIFS($P$22:$P30,$F$22:$F30,"BASIC")=1,O31*N31,0) -> 0.33333333 | Q31: e.g. flagged and closed the weakest vendor option
F32: ADVANCED | H32: Able to identify culture fit in current and potential employees | M32: No | N32: =1/COUNTA(H32:H35) -> 0.25 | O32: =IF(M32="Yes",1,0) -> 0 | P32: =IF(SUMIFS($P$22:$P31,$F$22:$F31,"INTERMEDIATE")=1,O32*N32,0) -> 0
F33: ADVANCED | H33: Knows in great detail strengths and weaknesses of their A-players | M33: No | N33: =N32 -> 0.25 | O33: =IF(M33="Yes",1,0) -> 0 | P33: =IF(SUMIFS($P$22:$P32,$F$22:$F32,"INTERMEDIATE")=1,O33*N33,0) -> 0
F34: ADVANCED | H34: Attracts and retains only A-players, puts them in the right position to win | M34: No | N34: =N33 -> 0.25 | O34: =IF(M34="Yes",1,0) -> 0 | P34: =IF(SUMIFS($P$22:$P33,$F$22:$F33,"INTERMEDIATE")=1,O34*N34,0) -> 0
F35: ADVANCED | H35: Successfully bets on people with exceptional return-on-investment | M35: No | N35: =N34 -> 0.25 | O35: =IF(M35="Yes",1,0) -> 0 | P35: =IF(SUMIFS($P$22:$P34,$F$22:$F34,"INTERMEDIATE")=1,O35*N35,0) -> 0
F36: EXCEPTIONAL | H36: A mastermind of people, re-defines industries and expectations | M36: No | N36: =1/COUNTA(H36:H38) -> 0.33333333 | O36: =IF(M36="Yes",1,0) -> 0 | P36: =IF(SUMIFS($P$22:$P35,$F$22:$F35,"ADVANCED")=1,O36*N36,0) -> 0
F37: EXPERT | H37: Has scientific approach to building a perfect team | M37: No | N37: =N36 -> 0.33333333 | O37: =IF(M37="Yes",1,0) -> 0 | P37: =IF(SUMIFS($P$22:$P36,$F$22:$F36,"ADVANCED")=1,O37*N37,0) -> 0
F38: EXPERT | H38: Able to identify and attract transformational hires to the company | M38: No | N38: =N37 -> 0.33333333 | O38: =IF(M38="Yes",1,0) -> 0 | P38: =IF(SUMIFS($P$22:$P37,$F$22:$F37,"ADVANCED")=1,O38*N38,0) -> 0 | V38: Your Grade: | W38: {=IFERROR(INDEX(Parameters!$B$5:$B$9,MATCH(SUM($P$22:$P$38),Parameters!$C$5:$C$9,0)),INDEX(Parameters!$B$5:$B$9,MATCH(SUM($P$22:$P$38),Parameters!$C$5:$C$9,1)))} -> Intermediate
D40: Push The Limits | F40: POOR | H40: Not driven by numbers or data | M40: No | N40: =1/COUNTA(H40:H44) -> 0.2 | O40: =IF(M40="No",1,0) -> 1 | P40: =O40*N40 -> 0.2
F41: POOR | H41: No structured approach | M41: No | N41: =N40 -> 0.2 | O41: =IF(M41="No",1,0) -> 1 | P41: =O41*N41 -> 0.2
F42: POOR | H42: Picks the easy option when challenged | M42: No | N42: =N41 -> 0.2 | O42: =IF(M42="No",1,0) -> 1 | P42: =O42*N42 -> 0.2
F43: POOR | H43: Relatively modest ambitions | M43: No | N43: =N42 -> 0.2 | O43: =IF(M43="No",1,0) -> 1 | P43: =O43*N43 -> 0.2
F44: POOR | H44: Weak logic, fantastical/utopian thinking patterns, mis-statements, exaggerations | M44: No | N44: =N43 -> 0.2 | O44: =IF(M44="No",1,0) -> 1 | P44: =O44*N44 -> 0.2
...

Sheet Parameters
B3: Scoring Scale
B4: Grade | C4: Score | D4: Score for Grading | E4: Score for Deliverables
B5: Poor | C5: 0 | D5: 0 | E5: 0
B6: Basic | C6: 1 | D6: 1.51 | E6: 8
B7: Intermediate | C7: 2.51 | D7: 2.51 | E7: 18
B8: Advanced | C8: 3.51 | D8: 3.51 | E8: 32
B9: Exceptional | C9: 4.51 | D9: 4.51 | E9: 50
B13: Competency Matrices
C15: Culture | F15: Deliverables | G15: Skills | J15: Number Version
C16: Dream Team | D16: Push the Limits | E16: Get it Done | F16: Deliverables | G16: Problem Solving | H16: Lifecycle Management | I16: Product Sense | J16: Dream Team | K16: Push the Limits | L16: Get it Done | M16: Deliverables | N16: Problem Solving | O16: Lifecycle Management | P16: Product Sense
B17: Junior | C17: Basic | D17: Basic | E17: Basic | F17: Basic | G17: Basic | H17: Basic | I17: Basic | J17: =INDEX($D$5:$D$9,MATCH(C17,$B$5:$B$9,0)) -> 1.51 | K17: =INDEX($D$5:$D$9,MATCH(D17,$B$5:$B$9,0)) -> 1.51 | L17: =INDEX($D$5:$D$9,MATCH(E17,$B$5:$B$9,0)) -> 1.51 | M17: =INDEX($D$5:$D$9,MATCH(F17,$B$5:$B$9,0)) -> 1.51 | N17: =INDEX($D$5:$D$9,MATCH(G17,$B$5:$B$9,0)) -> 1.51 | O17: =INDEX($D$5:$D$9,MATCH(H17,$B$5:$B$9,0)) -> 1.51 | P17: =INDEX($D$5:$D$9,MATCH(I17,$B$5:$B$9,0)) -> 1.51
B18: Mid | C18: Basic | D18: Basic | E18: Basic | F18: Intermediate | G18: Intermediate | H18: Basic | I18: Basic | J18: =INDEX($D$5:$D$9,MATCH(C18,$B$5:$B$9,0)) -> 1.51 | K18: =INDEX($D$5:$D$9,MATCH(D18,$B$5:$B$9,0)) -> 1.51 | L18: =INDEX($D$5:$D$9,MATCH(E18,$B$5:$B$9,0)) -> 1.51 | M18: =INDEX($D$5:$D$9,MATCH(F18,$B$5:$B$9,0)) -> 2.51 | N18: =INDEX($D$5:$D$9,MATCH(G18,$B$5:$B$9,0)) -> 2.51 | O18: =INDEX($D$5:$D$9,MATCH(H18,$B$5:$B$9,0)) -> 1.51 | P18: =INDEX($D$5:$D$9,MATCH(I18,$B$5:$B$9,0)) -> 1.51
B19: Senior | C19: Intermediate | D19: Basic | E19: Intermediate | F19: Intermediate | G19: Advanced | H19: Intermediate | I19: Intermediate | J19: =INDEX($D$5:$D$9,MATCH(C19,$B$5:$B$9,0)) -> 2.51 | K19: =INDEX($D$5:$D$9,MATCH(D19,$B$5:$B$9,0)) -> 1.51 | L19: =INDEX($D$5:$D$9,MATCH(E19,$B$5:$B$9,0)) -> 2.51 | M19: =INDEX($D$5:$D$9,MATCH(F19,$B$5:$B$9,0)) -> 2.51 | N19: =INDEX($D$5:$D$9,MATCH(G19,$B$5:$B$9,0)) -> 3.51 | O19: =INDEX($D$5:$D$9,MATCH(H19,$B$5:$B$9,0)) -> 2.51 | P19: =INDEX($D$5:$D$9,MATCH(I19,$B$5:$B$9,0)) -> 2.51
B20: Lead | C20: Advanced | D20: Intermediate | E20: Advanced | F20: Advanced | G20: Advanced | H20: Advanced | I20: Advanced | J20: =INDEX($D$5:$D$9,MATCH(C20,$B$5:$B$9,0)) -> 3.51 | K20: =INDEX($D$5:$D$9,MATCH(D20,$B$5:$B$9,0)) -> 2.51 | L20: =INDEX($D$5:$D$9,MATCH(E20,$B$5:$B$9,0)) -> 3.51 | M20: =INDEX($D$5:$D$9,MATCH(F20,$B$5:$B$9,0)) -> 3.51 | N20: =INDEX($D$5:$D$9,MATCH(G20,$B$5:$B$9,0)) -> 3.51 | O20: =INDEX($D$5:$D$9,MATCH(H20,$B$5:$B$9,0)) -> 3.51 | P20: =INDEX($D$5:$D$9,MATCH(I20,$B$5:$B$9,0)) -> 3.51
B22: Workings
B23: Employee Performance | J23: {=INDEX(Parameters!$D$5:$D$9,MATCH(INDEX('Assessment Scorecard'!$F$12:$F$19,MATCH(J$16,'Assessment Scorecard'!$D$12:$D$19,0)),Parameters!$B$5:$B$9,0))} -> 2.51 | K23: {=INDEX(Parameters!$D$5:$D$9,MATCH(INDEX('Assessment Scorecard'!$F$12:$F$19,MATCH(K$16,'Assessment Scorecard'!$D$12:$D$19,0)),Parameters!$B$5:$B$9,0))} -> 1.51 | L23: {=INDEX(Parameters!$D$5:$D$9,MATCH(INDEX('Assessment Scorecard'!$F$12:$F$19,MATCH(L$16,'Assessment Scorecard'!$D$12:$D$19,0)),Parameters!$B$5:$B$9,0))} -> 2.51 | M23: {=INDEX(Parameters!$D$5:$D$9,MATCH('Assessment Scorecard'!F15,Parameters!$B$5:$B$9,0))} -> 3.51 | N23: {=INDEX(Parameters!$D$5:$D$9,MATCH(INDEX('Assessment Scorecard'!$F$12:$F$19,MATCH(N$16,'Assessment Scorecard'!$D$12:$D$19,0)),Parameters!$B$5:$B$9,0))} -> 3.51 | O23: {=INDEX(Parameters!$D$5:$D$9,MATCH(INDEX('Assessment Scorecard'!$F$12:$F$19,MATCH(O$16,'Assessment Scorecard'!$D$12:$D$19,0)),Parameters!$B$5:$B$9,0))} -> 2.51 | P23: {=INDEX(Parameters!$D$5:$D$9,MATCH(INDEX('Assessment Scorecard'!$F$12:$F$19,MATCH(P$16,'Assessment Scorecard'!$D$12:$D$19,0)),Parameters!$B$5:$B$9,0))} -> 2.51
B24: Talent Bar | J24: {=INDEX(J$17:J$20,MATCH('Assessment Scorecard'!$F$5,$B$17:$B$20,0))} -> 1.51 | K24: {=INDEX(K$17:K$20,MATCH('Assessment Scorecard'!$F$5,$B$17:$B$20,0))} -> 1.51 | L24: {=INDEX(L$17:L$20,MATCH('Assessment Scorecard'!$F$5,$B$17:$B$20,0))} -> 1.51 | M24: {=INDEX(M$17:M$20,MATCH('Assessment Scorecard'!$F$5,$B$17:$B$20,0))} -> 2.51 | N24: {=INDEX(N$17:N$20,MATCH('Assessment Scorecard'!$F$5,$B$17:$B$20,0))} -> 2.51 | O24: {=INDEX(O$17:O$20,MATCH('Assessment Scorecard'!$F$5,$B$17:$B$20,0))} -> 1.51 | P24: {=INDEX(P$17:P$20,MATCH('Assessment Scorecard'!$F$5,$B$17:$B$20,0))} -> 1.51
B25: Diff | J25: =J23-J24 -> 1 | K25: =K23-K24 -> 0 | L25: =L23-L24 -> 1 | M25: =M23-M24 -> 1 | N25: =N23-N24 -> 1 | O25: =O23-O24 -> 1 | P25: =P23-P24 -> 1
